# Ex 9.16 (Corrigé)
> Throw; permet de relever l'exception

1\) Que va afficher ce programme ? 
```c++
#include <iostream>
#include <cstdlib>
using namespace std;

void f();

int main() {

   try {
      f();
   } catch (int n) {
      cout << "Exception int dans main : " << n << endl;   
   } catch (...) {
      cout << "Exception autre que int dans main" << endl;   
   }

   cout << "Fin main\n";   
   return EXIT_SUCCESS;
}

void f() {
   try {
      int n = 1;
      throw n;
   } catch (int n) {
      cout << "Exception int dans f : " << n << endl;   
      throw;
   }
}
```
1\) Ce programme affiche
```
Exception int dans f : 1
Exception int dans main : 1
Fin main
```
2\) Que va afficher ce programme (f a été remplacé)? 
```c++
#include <iostream>
#include <cstdlib>
using namespace std;

void f();

int main() {

   try {
      f();
   } catch (int n) {
      cout << "Exception int dans main : " << n << endl;   
   } catch (...) {
      cout << "Exception autre que int dans main" << endl;   
   }

   cout << "Fin main\n";   
   return EXIT_SUCCESS;
}

void f() {
   try {
      double x = 1.;
      throw x;
   } catch (int n) {
      cout << "Exception int dans f : " << n << endl;   
      throw;
   }
}
```
2\) Le programme affiche
```
Exception autre que int dans main
Fin main
``