# Ex 9.15 (corrigé)
> Terminate est appelé automatiquement s'il y a un throw, mais de catch l'intercepter  

> Quand un wsitch n'a pas de définition pour une valeur, le programme s'exécute normalement    

Que va afficher le programme ci-dessous, lorsque l'utilisateur saisit :  
1\) la valeur 1 ?  
2\) la valeur 2 ?  
3\) la valeur 3 ?  
4\) la valeur 4 ?  

```c++
#include <cstdlib>
#include <iostream>
#include <exception>
using namespace std;

void onExit() {
   cout << "Appel de exit\n";
}

void onTerminate() {
   cout << "Appel de terminate\n";
   exit(EXIT_FAILURE); // pour éviter que le programme ne "plante"
}

int main() {

   atexit(onExit);
   set_terminate(onTerminate);

   int n;
   float x;
   double y;

   cout << "Donnez un entier : ";
   cin >> n;

   try {
      switch (n) {
         case 1: throw n;
         case 2: x = (float)n;  throw x;
         case 3: y = (double)n; throw y;
      }
   } catch (int n) {
      cout << "catch(int n) : n = " << n << endl;
   } catch (float x) {
      cout << "catch(float x) : x = " << x << endl;
      exit(EXIT_FAILURE);
   }

   cout << "Fin du programme\n";

   return EXIT_SUCCESS;
}
```
1\) Valeur 1  
```
Donnez un entier : 1
catch(int n) : n = 1
Fin du programme
Appel de exit
```
2\) Valeur 2
```
Donnez un entier : 2
catch(float x) : x = 2
Appel de exit
```
3\) Valeur 3
```
Donnez un entier : 3
Appel de terminate
Appel de exit
```
3\) Valeur 4
```
Donnez un entier : 4
Fin du programme
Appel de exit
```